2019-09-04 16:59:48,992 ERROR: Exception on /post/2 [POST] [in c:\users\dreamcast\documents\blog\venv\lib\site-packages\flask\app.py:1891]
Traceback (most recent call last):
  File "c:\users\dreamcast\documents\blog\venv\lib\site-packages\flask\app.py", line 2446, in wsgi_app
    response = self.full_dispatch_request()
  File "c:\users\dreamcast\documents\blog\venv\lib\site-packages\flask\app.py", line 1951, in full_dispatch_request
    rv = self.handle_user_exception(e)
  File "c:\users\dreamcast\documents\blog\venv\lib\site-packages\flask\app.py", line 1820, in handle_user_exception
    reraise(exc_type, exc_value, tb)
  File "c:\users\dreamcast\documents\blog\venv\lib\site-packages\flask\_compat.py", line 39, in reraise
    raise value
  File "c:\users\dreamcast\documents\blog\venv\lib\site-packages\flask\app.py", line 1949, in full_dispatch_request
    rv = self.dispatch_request()
  File "c:\users\dreamcast\documents\blog\venv\lib\site-packages\flask\app.py", line 1935, in dispatch_request
    return self.view_functions[rule.endpoint](**req.view_args)
  File "c:\users\dreamcast\documents\blog\venv\lib\site-packages\flask_login\utils.py", line 261, in decorated_view
    return func(*args, **kwargs)
  File "C:\Users\Dreamcast\Documents\blog\main\urls.py", line 151, in post
    comment = Comment(body=form.comment.data, author=current_user)
  File "<string>", line 4, in __init__
  File "c:\users\dreamcast\documents\blog\venv\lib\site-packages\sqlalchemy\orm\state.py", line 441, in _initialize_instance
    manager.dispatch.init_failure(self, args, kwargs)
  File "c:\users\dreamcast\documents\blog\venv\lib\site-packages\sqlalchemy\util\langhelpers.py", line 68, in __exit__
    compat.reraise(exc_type, exc_value, exc_tb)
  File "c:\users\dreamcast\documents\blog\venv\lib\site-packages\sqlalchemy\util\compat.py", line 153, in reraise
    raise value
  File "c:\users\dreamcast\documents\blog\venv\lib\site-packages\sqlalchemy\orm\state.py", line 438, in _initialize_instance
    return manager.original_init(*mixed[1:], **kwargs)
  File "c:\users\dreamcast\documents\blog\venv\lib\site-packages\sqlalchemy\ext\declarative\base.py", line 840, in _declarative_constructor
    "%r is an invalid keyword argument for %s" % (k, cls_.__name__)
TypeError: 'author' is an invalid keyword argument for Comment
2019-09-05 01:01:56,513 INFO: Blog Network startup [in C:\Users\Dreamcast\Documents\blog\main\__init__.py:33]
2019-09-05 01:02:13,864 INFO: Blog Network startup [in C:\Users\Dreamcast\Documents\blog\main\__init__.py:33]
2019-09-05 01:02:21,167 INFO: Blog Network startup [in C:\Users\Dreamcast\Documents\blog\main\__init__.py:33]
2019-09-05 01:02:33,092 ERROR: Exception on /post/3 [GET] [in c:\users\dreamcast\documents\blog\venv\lib\site-packages\flask\app.py:1891]
Traceback (most recent call last):
  File "c:\users\dreamcast\documents\blog\venv\lib\site-packages\flask\app.py", line 2446, in wsgi_app
    response = self.full_dispatch_request()
  File "c:\users\dreamcast\documents\blog\venv\lib\site-packages\flask\app.py", line 1951, in full_dispatch_request
    rv = self.handle_user_exception(e)
  File "c:\users\dreamcast\documents\blog\venv\lib\site-packages\flask\app.py", line 1820, in handle_user_exception
    reraise(exc_type, exc_value, tb)
  File "c:\users\dreamcast\documents\blog\venv\lib\site-packages\flask\_compat.py", line 39, in reraise
    raise value
  File "c:\users\dreamcast\documents\blog\venv\lib\site-packages\flask\app.py", line 1949, in full_dispatch_request
    rv = self.dispatch_request()
  File "c:\users\dreamcast\documents\blog\venv\lib\site-packages\flask\app.py", line 1935, in dispatch_request
    return self.view_functions[rule.endpoint](**req.view_args)
  File "c:\users\dreamcast\documents\blog\venv\lib\site-packages\flask_login\utils.py", line 261, in decorated_view
    return func(*args, **kwargs)
  File "C:\Users\Dreamcast\Documents\blog\main\urls.py", line 157, in post
    comments = Comment.query.filter_by(id=in_response_to)
NameError: name 'in_response_to' is not defined
2019-09-05 01:05:00,325 INFO: Blog Network startup [in C:\Users\Dreamcast\Documents\blog\main\__init__.py:33]
2019-09-05 01:05:01,825 ERROR: Exception on /post/3 [GET] [in c:\users\dreamcast\documents\blog\venv\lib\site-packages\flask\app.py:1891]
Traceback (most recent call last):
  File "c:\users\dreamcast\documents\blog\venv\lib\site-packages\flask\app.py", line 2446, in wsgi_app
    response = self.full_dispatch_request()
  File "c:\users\dreamcast\documents\blog\venv\lib\site-packages\flask\app.py", line 1951, in full_dispatch_request
    rv = self.handle_user_exception(e)
  File "c:\users\dreamcast\documents\blog\venv\lib\site-packages\flask\app.py", line 1820, in handle_user_exception
    reraise(exc_type, exc_value, tb)
  File "c:\users\dreamcast\documents\blog\venv\lib\site-packages\flask\_compat.py", line 39, in reraise
    raise value
  File "c:\users\dreamcast\documents\blog\venv\lib\site-packages\flask\app.py", line 1949, in full_dispatch_request
    rv = self.dispatch_request()
  File "c:\users\dreamcast\documents\blog\venv\lib\site-packages\flask\app.py", line 1935, in dispatch_request
    return self.view_functions[rule.endpoint](**req.view_args)
  File "c:\users\dreamcast\documents\blog\venv\lib\site-packages\flask_login\utils.py", line 261, in decorated_view
    return func(*args, **kwargs)
  File "C:\Users\Dreamcast\Documents\blog\main\urls.py", line 157, in post
    comments = Comment.query.filter_by(id=Comment.c.in_response_to)
AttributeError: type object 'Comment' has no attribute 'c'
2019-09-05 01:06:35,261 INFO: Blog Network startup [in C:\Users\Dreamcast\Documents\blog\main\__init__.py:33]
2019-09-05 01:09:28,579 INFO: Blog Network startup [in C:\Users\Dreamcast\Documents\blog\main\__init__.py:33]
2019-09-05 01:15:22,741 INFO: Blog Network startup [in C:\Users\Dreamcast\Documents\blog\main\__init__.py:33]
2019-09-05 01:15:24,670 ERROR: Exception on /post/2 [GET] [in c:\users\dreamcast\documents\blog\venv\lib\site-packages\flask\app.py:1891]
Traceback (most recent call last):
  File "c:\users\dreamcast\documents\blog\venv\lib\site-packages\sqlalchemy\orm\attributes.py", line 227, in __getattr__
    return getattr(self.comparator, key)
AttributeError: 'Comparator' object has no attribute 'id'

During handling of the above exception, another exception occurred:

Traceback (most recent call last):
  File "c:\users\dreamcast\documents\blog\venv\lib\site-packages\flask\app.py", line 2446, in wsgi_app
    response = self.full_dispatch_request()
  File "c:\users\dreamcast\documents\blog\venv\lib\site-packages\flask\app.py", line 1951, in full_dispatch_request
    rv = self.handle_user_exception(e)
  File "c:\users\dreamcast\documents\blog\venv\lib\site-packages\flask\app.py", line 1820, in handle_user_exception
    reraise(exc_type, exc_value, tb)
  File "c:\users\dreamcast\documents\blog\venv\lib\site-packages\flask\_compat.py", line 39, in reraise
    raise value
  File "c:\users\dreamcast\documents\blog\venv\lib\site-packages\flask\app.py", line 1949, in full_dispatch_request
    rv = self.dispatch_request()
  File "c:\users\dreamcast\documents\blog\venv\lib\site-packages\flask\app.py", line 1935, in dispatch_request
    return self.view_functions[rule.endpoint](**req.view_args)
  File "c:\users\dreamcast\documents\blog\venv\lib\site-packages\flask_login\utils.py", line 261, in decorated_view
    return func(*args, **kwargs)
  File "C:\Users\Dreamcast\Documents\blog\main\urls.py", line 157, in post
    comments = Comment.query.filter_by(id=Comment.source.id)
  File "c:\users\dreamcast\documents\blog\venv\lib\site-packages\sqlalchemy\orm\attributes.py", line 236, in __getattr__
    key,
AttributeError: Neither 'InstrumentedAttribute' object nor 'Comparator' object associated with Comment.source has an attribute 'id'
2019-09-05 01:16:10,880 INFO: Blog Network startup [in C:\Users\Dreamcast\Documents\blog\main\__init__.py:33]
2019-09-05 01:16:12,606 ERROR: Exception on /post/2 [GET] [in c:\users\dreamcast\documents\blog\venv\lib\site-packages\flask\app.py:1891]
Traceback (most recent call last):
  File "c:\users\dreamcast\documents\blog\venv\lib\site-packages\flask\app.py", line 2446, in wsgi_app
    response = self.full_dispatch_request()
  File "c:\users\dreamcast\documents\blog\venv\lib\site-packages\flask\app.py", line 1951, in full_dispatch_request
    rv = self.handle_user_exception(e)
  File "c:\users\dreamcast\documents\blog\venv\lib\site-packages\flask\app.py", line 1820, in handle_user_exception
    reraise(exc_type, exc_value, tb)
  File "c:\users\dreamcast\documents\blog\venv\lib\site-packages\flask\_compat.py", line 39, in reraise
    raise value
  File "c:\users\dreamcast\documents\blog\venv\lib\site-packages\flask\app.py", line 1949, in full_dispatch_request
    rv = self.dispatch_request()
  File "c:\users\dreamcast\documents\blog\venv\lib\site-packages\flask\app.py", line 1935, in dispatch_request
    return self.view_functions[rule.endpoint](**req.view_args)
  File "c:\users\dreamcast\documents\blog\venv\lib\site-packages\flask_login\utils.py", line 261, in decorated_view
    return func(*args, **kwargs)
  File "C:\Users\Dreamcast\Documents\blog\main\urls.py", line 157, in post
    comments = Comment.query.filter_by(id=comment.source.id)
UnboundLocalError: local variable 'comment' referenced before assignment
2019-09-05 01:17:45,493 INFO: Blog Network startup [in C:\Users\Dreamcast\Documents\blog\main\__init__.py:33]
2019-09-05 15:01:30,008 INFO: Blog Network startup [in C:\Users\Dreamcast\Documents\blog\main\__init__.py:33]
2019-09-05 15:10:21,672 INFO: Blog Network startup [in C:\Users\Dreamcast\Documents\blog\main\__init__.py:33]
2019-09-05 15:18:49,396 INFO: Blog Network startup [in C:\Users\Dreamcast\Documents\blog\main\__init__.py:33]
2019-09-05 20:55:15,870 INFO: Blog Network startup [in C:\Users\Dreamcast\Documents\blog\main\__init__.py:38]
2019-09-05 20:55:22,143 INFO: Blog Network startup [in C:\Users\Dreamcast\Documents\blog\main\__init__.py:38]
